2019-02-24 03:05:15,646 ERROR: Exception on /login [POST] [in /home/alex/crmdancer/venv/lib/python3.7/site-packages/flask/app.py:1587]
Traceback (most recent call last):
  File "/home/alex/crmdancer/venv/lib/python3.7/site-packages/sqlalchemy/util/_collections.py", line 1005, in __call__
    return self.registry[key]
KeyError: 140440451372544

During handling of the above exception, another exception occurred:

Traceback (most recent call last):
  File "/home/alex/crmdancer/venv/lib/python3.7/site-packages/flask/app.py", line 1988, in wsgi_app
    response = self.full_dispatch_request()
  File "/home/alex/crmdancer/venv/lib/python3.7/site-packages/flask/app.py", line 1641, in full_dispatch_request
    rv = self.handle_user_exception(e)
  File "/home/alex/crmdancer/venv/lib/python3.7/site-packages/flask/app.py", line 1544, in handle_user_exception
    reraise(exc_type, exc_value, tb)
  File "/home/alex/crmdancer/venv/lib/python3.7/site-packages/flask/_compat.py", line 33, in reraise
    raise value
  File "/home/alex/crmdancer/venv/lib/python3.7/site-packages/flask/app.py", line 1639, in full_dispatch_request
    rv = self.dispatch_request()
  File "/home/alex/crmdancer/venv/lib/python3.7/site-packages/flask/app.py", line 1625, in dispatch_request
    return self.view_functions[rule.endpoint](**req.view_args)
  File "/home/alex/crmdancer/main.py", line 157, in login
    row = User.query.filter_by(login=f['usern'], passw=f['passw']).first()
  File "/home/alex/crmdancer/venv/lib/python3.7/site-packages/flask_sqlalchemy/__init__.py", line 514, in __get__
    return type.query_class(mapper, session=self.sa.session())
  File "/home/alex/crmdancer/venv/lib/python3.7/site-packages/sqlalchemy/orm/scoping.py", line 78, in __call__
    return self.registry()
  File "/home/alex/crmdancer/venv/lib/python3.7/site-packages/sqlalchemy/util/_collections.py", line 1007, in __call__
    return self.registry.setdefault(key, self.createfunc())
  File "/home/alex/crmdancer/venv/lib/python3.7/site-packages/sqlalchemy/orm/session.py", line 3181, in __call__
    return self.class_(**local_kw)
  File "/home/alex/crmdancer/venv/lib/python3.7/site-packages/flask_sqlalchemy/__init__.py", line 143, in __init__
    bind = options.pop('bind', None) or db.engine
  File "/home/alex/crmdancer/venv/lib/python3.7/site-packages/flask_sqlalchemy/__init__.py", line 877, in engine
    return self.get_engine()
  File "/home/alex/crmdancer/venv/lib/python3.7/site-packages/flask_sqlalchemy/__init__.py", line 896, in get_engine
    return connector.get_engine()
  File "/home/alex/crmdancer/venv/lib/python3.7/site-packages/flask_sqlalchemy/__init__.py", line 559, in get_engine
    self._engine = rv = sqlalchemy.create_engine(info, **options)
  File "/home/alex/crmdancer/venv/lib/python3.7/site-packages/sqlalchemy/engine/__init__.py", line 431, in create_engine
    return strategy.create(*args, **kwargs)
  File "/home/alex/crmdancer/venv/lib/python3.7/site-packages/sqlalchemy/engine/strategies.py", line 87, in create
    dbapi = dialect_cls.dbapi(**dbapi_args)
  File "/home/alex/crmdancer/venv/lib/python3.7/site-packages/sqlalchemy/dialects/mysql/mysqlconnector.py", line 160, in dbapi
    from mysql import connector
ModuleNotFoundError: No module named 'mysql'
2019-02-24 03:06:10,084 ERROR: Exception on /login [POST] [in /home/alex/crmdancer/venv/lib/python3.7/site-packages/flask/app.py:1587]
Traceback (most recent call last):
  File "/home/alex/crmdancer/venv/lib/python3.7/site-packages/sqlalchemy/util/_collections.py", line 1005, in __call__
    return self.registry[key]
KeyError: 140282253186560

During handling of the above exception, another exception occurred:

Traceback (most recent call last):
  File "/home/alex/crmdancer/venv/lib/python3.7/site-packages/flask/app.py", line 1988, in wsgi_app
    response = self.full_dispatch_request()
  File "/home/alex/crmdancer/venv/lib/python3.7/site-packages/flask/app.py", line 1641, in full_dispatch_request
    rv = self.handle_user_exception(e)
  File "/home/alex/crmdancer/venv/lib/python3.7/site-packages/flask/app.py", line 1544, in handle_user_exception
    reraise(exc_type, exc_value, tb)
  File "/home/alex/crmdancer/venv/lib/python3.7/site-packages/flask/_compat.py", line 33, in reraise
    raise value
  File "/home/alex/crmdancer/venv/lib/python3.7/site-packages/flask/app.py", line 1639, in full_dispatch_request
    rv = self.dispatch_request()
  File "/home/alex/crmdancer/venv/lib/python3.7/site-packages/flask/app.py", line 1625, in dispatch_request
    return self.view_functions[rule.endpoint](**req.view_args)
  File "/home/alex/crmdancer/main.py", line 157, in login
    row = User.query.filter_by(login=f['usern'], passw=f['passw']).first()
  File "/home/alex/crmdancer/venv/lib/python3.7/site-packages/flask_sqlalchemy/__init__.py", line 514, in __get__
    return type.query_class(mapper, session=self.sa.session())
  File "/home/alex/crmdancer/venv/lib/python3.7/site-packages/sqlalchemy/orm/scoping.py", line 78, in __call__
    return self.registry()
  File "/home/alex/crmdancer/venv/lib/python3.7/site-packages/sqlalchemy/util/_collections.py", line 1007, in __call__
    return self.registry.setdefault(key, self.createfunc())
  File "/home/alex/crmdancer/venv/lib/python3.7/site-packages/sqlalchemy/orm/session.py", line 3181, in __call__
    return self.class_(**local_kw)
  File "/home/alex/crmdancer/venv/lib/python3.7/site-packages/flask_sqlalchemy/__init__.py", line 143, in __init__
    bind = options.pop('bind', None) or db.engine
  File "/home/alex/crmdancer/venv/lib/python3.7/site-packages/flask_sqlalchemy/__init__.py", line 877, in engine
    return self.get_engine()
  File "/home/alex/crmdancer/venv/lib/python3.7/site-packages/flask_sqlalchemy/__init__.py", line 896, in get_engine
    return connector.get_engine()
  File "/home/alex/crmdancer/venv/lib/python3.7/site-packages/flask_sqlalchemy/__init__.py", line 559, in get_engine
    self._engine = rv = sqlalchemy.create_engine(info, **options)
  File "/home/alex/crmdancer/venv/lib/python3.7/site-packages/sqlalchemy/engine/__init__.py", line 431, in create_engine
    return strategy.create(*args, **kwargs)
  File "/home/alex/crmdancer/venv/lib/python3.7/site-packages/sqlalchemy/engine/strategies.py", line 87, in create
    dbapi = dialect_cls.dbapi(**dbapi_args)
  File "/home/alex/crmdancer/venv/lib/python3.7/site-packages/sqlalchemy/dialects/mysql/mysqlconnector.py", line 160, in dbapi
    from mysql import connector
ModuleNotFoundError: No module named 'mysql'
